<?xml version='1.0' encoding='utf-8'?>
<robot name="sphere">

    <link name="link0">
      <inertial>
        <origin xyz="0 0 0" rpy="0 0 0" />
        <mass value="0.01" />
        <inertia ixx="0.001" iyy="0.001" izz="0.001" ixy="0" ixz="0" iyz="0" />
      </inertial>
    </link>

    <link name="link1">
      <inertial>
        <origin xyz="0 0 0" rpy="0 -0 0" />
        <mass value="0.01" />
        <inertia ixx="0.001" iyy="0.001" izz="0.001" ixy="0" ixz="0" iyz="0" />
      </inertial>
    </link>

    <link name="link2">
      <inertial>
        <origin xyz="0 0 0" rpy="0 -0 0" />
        <mass value="0.01" />
        <inertia ixx="0.001" iyy="0.001" izz="0.001" ixy="0" ixz="0" iyz="0" />
      </inertial>
    </link>

    <link name="end_effector">
      <inertial>
        <origin xyz="0 0 0" rpy="0 -0 0" />
        <mass value="1" />
        <inertia ixx="0.2" iyy="0.2" izz="0.2" ixy="0" ixz="0" iyz="0" />
      </inertial>
      <visual>
        <geometry>
          <sphere radius="0.03" />
        </geometry>
      </visual>
      <collision>
        <geometry>
          <sphere radius="0.03" />
        </geometry>
      </collision>
    </link>


    <joint name="joint1" type="prismatic">
      <safety_controller k_position="100.0" k_velocity="40.0" soft_lower_limit="-2.8973" soft_upper_limit="2.8973"/>
      <origin rpy="0 0 0" xyz="0 0 0"/>
      <parent link="link0"/>
      <child link="link1"/>
      <axis xyz="1 0 0"/>
      <limit effort="87" lower="-2.8973" upper="2.8973" velocity="2.1750"/>
    </joint>

    <joint name="joint2" type="prismatic">
      <safety_controller k_position="100.0" k_velocity="40.0" soft_lower_limit="-1.7628" soft_upper_limit="1.7628"/>
      <origin rpy="0 0 0" xyz="0 0 0"/>
      <parent link="link1"/>
      <child link="link2"/>
      <axis xyz="0 1 0"/>
      <limit effort="87" lower="-1.7628" upper="1.7628" velocity="2.1750"/>
    </joint>

    <joint name="joint3" type="prismatic">
      <safety_controller k_position="100.0" k_velocity="40.0" soft_lower_limit="-2.8973" soft_upper_limit="2.8973"/>
      <origin rpy="0 0 0" xyz="0 0 0"/>
      <parent link="link2"/>
      <child link="end_effector"/>
      <axis xyz="0 0 1"/>
      <limit effort="87" lower="-2.8973" upper="2.8973" velocity="2.1750"/>
    </joint>


</robot>
